Workbook

Sheet Production
A1: Assumption
A2: capital's share | B2: 0.35
A3: annual depreciation rate | B3: =AVERAGE('CFC data'!$E$22:$E$29)
K4: HP Filter | O4: lambda | P4: 100
D5: K | E5: Real GDP | F5: LnK | G5: LnY | K5: LnZ | L5: LnZ_HP | M5: Second-order difference | N5: LnA-Trend(Check) | O5: objective | P5: =SUMSQ($N$6:$N$27)+$P$4*SUMSQ($M$8:$M$27)
C6: 2002 | D6: =INDEX(PWT!$B$2:$B$35, MATCH($C6, PWT!$A$2:$A$35, 0)) | E6: =INDEX(WEO_Data!$C$8:$C$51, MATCH($C6, WEO_Data!$B$8:$B$51, 0))*1000 | F6: =LN(D6) | G6: =LN(E6) | K6: =G6-$B$2*F6 | L6: =K6 | N6: =L6-K6
C7: 2003 | D7: =INDEX(PWT!$B$2:$B$35, MATCH($C7, PWT!$A$2:$A$35, 0)) | E7: =INDEX(WEO_Data!$C$8:$C$51, MATCH($C7, WEO_Data!$B$8:$B$51, 0))*1000 | F7: =LN(D7) | G7: =LN(E7) | K7: =G7-$B$2*F7 | L7: =K7 | N7: =L7-K7
C8: 2004 | D8: =INDEX(PWT!$B$2:$B$35, MATCH($C8, PWT!$A$2:$A$35, 0)) | E8: =INDEX(WEO_Data!$C$8:$C$51, MATCH($C8, WEO_Data!$B$8:$B$51, 0))*1000 | F8: =LN(D8) | G8: =LN(E8) | K8: =G8-$B$2*F8 | L8: =K8 | M8: =L8-2*L7+L6 | N8: =L8-K8
C9: 2005 | D9: =INDEX(PWT!$B$2:$B$35, MATCH($C9, PWT!$A$2:$A$35, 0)) | E9: =INDEX(WEO_Data!$C$8:$C$51, MATCH($C9, WEO_Data!$B$8:$B$51, 0))*1000 | F9: =LN(D9) | G9: =LN(E9) | K9: =G9-$B$2*F9 | L9: =K9 | M9: =L9-2*L8+L7 | N9: =L9-K9
C10: 2006 | D10: =INDEX(PWT!$B$2:$B$35, MATCH($C10, PWT!$A$2:$A$35, 0)) | E10: =INDEX(WEO_Data!$C$8:$C$51, MATCH($C10, WEO_Data!$B$8:$B$51, 0))*1000 | F10: =LN(D10) | G10: =LN(E10) | K10: =G10-$B$2*F10 | L10: =K10 | M10: =L10-2*L9+L8 | N10: =L10-K10
C11: 2007 | D11: =INDEX(PWT!$B$2:$B$35, MATCH($C11, PWT!$A$2:$A$35, 0)) | E11: =INDEX(WEO_Data!$C$8:$C$51, MATCH($C11, WEO_Data!$B$8:$B$51, 0))*1000 | F11: =LN(D11) | G11: =LN(E11) | K11: =G11-$B$2*F11 | L11: =K11 | M11: =L11-2*L10+L9 | N11: =L11-K11
C12: 2008 | D12: =INDEX(PWT!$B$2:$B$35, MATCH($C12, PWT!$A$2:$A$35, 0)) | E12: =INDEX(WEO_Data!$C$8:$C$51, MATCH($C12, WEO_Data!$B$8:$B$51, 0))*1000 | F12: =LN(D12) | G12: =LN(E12) | K12: =G12-$B$2*F12 | L12: =K12 | M12: =L12-2*L11+L10 | N12: =L12-K12
C13: 2009 | D13: =INDEX(PWT!$B$2:$B$35, MATCH($C13, PWT!$A$2:$A$35, 0)) | E13: =INDEX(WEO_Data!$C$8:$C$51, MATCH($C13, WEO_Data!$B$8:$B$51, 0))*1000 | F13: =LN(D13) | G13: =LN(E13) | K13: =G13-$B$2*F13 | L13: =K13 | M13: =L13-2*L12+L11 | N13: =L13-K13
C14: 2010 | D14: =INDEX(PWT!$B$2:$B$35, MATCH($C14, PWT!$A$2:$A$35, 0)) | E14: =INDEX(WEO_Data!$C$8:$C$51, MATCH($C14, WEO_Data!$B$8:$B$51, 0))*1000 | F14: =LN(D14) | G14: =LN(E14) | K14: =G14-$B$2*F14 | L14: =K14 | M14: =L14-2*L13+L12 | N14: =L14-K14
C15: 2011 | D15: =INDEX(PWT!$B$2:$B$35, MATCH($C15, PWT!$A$2:$A$35, 0)) | E15: =INDEX(WEO_Data!$C$8:$C$51, MATCH($C15, WEO_Data!$B$8:$B$51, 0))*1000 | F15: =LN(D15) | G15: =LN(E15) | K15: =G15-$B$2*F15 | L15: =K15 | M15: =L15-2*L14+L13 | N15: =L15-K15
C16: 2012 | D16: =INDEX(PWT!$B$2:$B$35, MATCH($C16, PWT!$A$2:$A$35, 0)) | E16: =INDEX(WEO_Data!$C$8:$C$51, MATCH($C16, WEO_Data!$B$8:$B$51, 0))*1000 | F16: =LN(D16) | G16: =LN(E16) | K16: =G16-$B$2*F16 | L16: =K16 | M16: =L16-2*L15+L14 | N16: =L16-K16
C17: 2013 | D17: =INDEX(PWT!$B$2:$B$35, MATCH($C17, PWT!$A$2:$A$35, 0)) | E17: =INDEX(WEO_Data!$C$8:$C$51, MATCH($C17, WEO_Data!$B$8:$B$51, 0))*1000 | F17: =LN(D17) | G17: =LN(E17) | K17: =G17-$B$2*F17 | L17: =K17 | M17: =L17-2*L16+L15 | N17: =L17-K17
C18: 2014 | D18: =INDEX(PWT!$B$2:$B$35, MATCH($C18, PWT!$A$2:$A$35, 0)) | E18: =INDEX(WEO_Data!$C$8:$C$51, MATCH($C18, WEO_Data!$B$8:$B$51, 0))*1000 | F18: =LN(D18) | G18: =LN(E18) | K18: =G18-$B$2*F18 | L18: =K18 | M18: =L18-2*L17+L16 | N18: =L18-K18
C19: 2015 | D19: =INDEX(PWT!$B$2:$B$35, MATCH($C19, PWT!$A$2:$A$35, 0)) | E19: =INDEX(WEO_Data!$C$8:$C$51, MATCH($C19, WEO_Data!$B$8:$B$51, 0))*1000 | F19: =LN(D19) | G19: =LN(E19) | K19: =G19-$B$2*F19 | L19: =K19 | M19: =L19-2*L18+L17 | N19: =L19-K19
... C27: 2023 | D27: =INDEX(PWT!$B$2:$B$35, MATCH($C27, PWT!$A$2:$A$35, 0)) | E27: =INDEX(WEO_Data!$C$8:$C$51, MATCH($C27, WEO_Data!$B$8:$B$51, 0))*1000 | F27: =LN(D27) | G27: =LN(E27) | K27: =G27-$B$2*F27 | L27: =K27 | M27: =L27-2*L26+L25 | N27: =L27-K27
C34: Anchor K/Y (avg last 9 yrs) | D34: =AVERAGE(D49:D57)
D35: K/Y | E35: K | F35: Y | G35: LnZ trend | H35: Ystar_base | I35: Investment | J35: ΔK | K35: K_With | L35: Ystar_with | M35: Uplift | N35: Projected GDP | O35: Projected GDP Growth | P35: Baseline GDP Growth
C36: 2002 | D36: =IFERROR(E36/F36,"") | E36: =IF($C36<=2023,INDEX(PWT!$B$2:$B$35, MATCH($C36, PWT!$A$2:$A$35, 0)),$D$34*F36) | F36: =INDEX(WEO_Data!$C$8:$C$51, MATCH($C36, WEO_Data!$B$8:$B$51, 0))*1000 | G36: =IF($C36<=2023,INDEX($L$6:$L$27, MATCH($C36, $C$6:$C$27, 0)),TREND($L$6:$L$27, $C$6:$C$27, $C36)) | H36: =EXP(G36+$B$2*LN(E36)) | I36: =IF(AND($C36>=2026,$C36<=2033),INDEX(Investment!$C$2:$C$9, MATCH($C36, Investment!$B$2:$B$9, 0)),0) | J36: 0 | K36: =E36+J36 | L36: =EXP(G36+$B$2*LN(K36)) | M36: =L36-H36 | N36: =F36+M36 | P36: =INDEX(WEO_Data!$D$8:$D$51, MATCH($C36, WEO_Data!$B$8:$B$51, 0))/100
C37: 2003 | D37: =IFERROR(E37/F37,"") | E37: =IF($C37<=2023,INDEX(PWT!$B$2:$B$35, MATCH($C37, PWT!$A$2:$A$35, 0)),$D$34*F37) | F37: =INDEX(WEO_Data!$C$8:$C$51, MATCH($C37, WEO_Data!$B$8:$B$51, 0))*1000 | G37: =IF($C37<=2023,INDEX($L$6:$L$27, MATCH($C37, $C$6:$C$27, 0)),TREND($L$6:$L$27, $C$6:$C$27, $C37)) | H37: =EXP(G37+$B$2*LN(E37)) | I37: =IF(AND($C37>=2026,$C37<=2033),INDEX(Investment!$C$2:$C$9, MATCH($C37, Investment!$B$2:$B$9, 0)),0) | J37: =IF($C37<2026,0,(1-$B$3)*J36+I37) | K37: =E37+J37 | L37: =EXP(G37+$B$2*LN(K37)) | M37: =L37-H37 | N37: =F37+M37 | O37: =IFERROR(N37/N36-1,"") | P37: =INDEX(WEO_Data!$D$8:$D$51, MATCH($C37, WEO_Data!$B$8:$B$51, 0))/100
C38: 2004 | D38: =IFERROR(E38/F38,"") | E38: =IF($C38<=2023,INDEX(PWT!$B$2:$B$35, MATCH($C38, PWT!$A$2:$A$35, 0)),$D$34*F38) | F38: =INDEX(WEO_Data!$C$8:$C$51, MATCH($C38, WEO_Data!$B$8:$B$51, 0))*1000 | G38: =IF($C38<=2023,INDEX($L$6:$L$27, MATCH($C38, $C$6:$C$27, 0)),TREND($L$6:$L$27, $C$6:$C$27, $C38)) | H38: =EXP(G38+$B$2*LN(E38)) | I38: =IF(AND($C38>=2026,$C38<=2033),INDEX(Investment!$C$2:$C$9, MATCH($C38, Investment!$B$2:$B$9, 0)),0) | J38: =IF($C38<2026,0,(1-$B$3)*J37+I38) | K38: =E38+J38 | L38: =EXP(G38+$B$2*LN(K38)) | M38: =L38-H38 | N38: =F38+M38 | O38: =IFERROR(N38/N37-1,"") | P38: =INDEX(WEO_Data!$D$8:$D$51, MATCH($C38, WEO_Data!$B$8:$B$51, 0))/100
C39: 2005 | D39: =IFERROR(E39/F39,"") | E39: =IF($C39<=2023,INDEX(PWT!$B$2:$B$35, MATCH($C39, PWT!$A$2:$A$35, 0)),$D$34*F39) | F39: =INDEX(WEO_Data!$C$8:$C$51, MATCH($C39, WEO_Data!$B$8:$B$51, 0))*1000 | G39: =IF($C39<=2023,INDEX($L$6:$L$27, MATCH($C39, $C$6:$C$27, 0)),TREND($L$6:$L$27, $C$6:$C$27, $C39)) | H39: =EXP(G39+$B$2*LN(E39)) | I39: =IF(AND($C39>=2026,$C39<=2033),INDEX(Investment!$C$2:$C$9, MATCH($C39, Investment!$B$2:$B$9, 0)),0) | J39: =IF($C39<2026,0,(1-$B$3)*J38+I39) | K39: =E39+J39 | L39: =EXP(G39+$B$2*LN(K39)) | M39: =L39-H39 | N39: =F39+M39 | O39: =IFERROR(N39/N38-1,"") | P39: =INDEX(WEO_Data!$D$8:$D$51, MATCH($C39, WEO_Data!$B$8:$B$51, 0))/100
C40: 2006 | D40: =IFERROR(E40/F40,"") | E40: =IF($C40<=2023,INDEX(PWT!$B$2:$B$35, MATCH($C40, PWT!$A$2:$A$35, 0)),$D$34*F40) | F40: =INDEX(WEO_Data!$C$8:$C$51, MATCH($C40, WEO_Data!$B$8:$B$51, 0))*1000 | G40: =IF($C40<=2023,INDEX($L$6:$L$27, MATCH($C40, $C$6:$C$27, 0)),TREND($L$6:$L$27, $C$6:$C$27, $C40)) | H40: =EXP(G40+$B$2*LN(E40)) | I40: =IF(AND($C40>=2026,$C40<=2033),INDEX(Investment!$C$2:$C$9, MATCH($C40, Investment!$B$2:$B$9, 0)),0) | J40: =IF($C40<2026,0,(1-$B$3)*J39+I40) | K40: =E40+J40 | L40: =EXP(G40+$B$2*LN(K40)) | M40: =L40-H40 | N40: =F40+M40 | O40: =IFERROR(N40/N39-1,"") | P40: =INDEX(WEO_Data!$D$8:$D$51, MATCH($C40, WEO_Data!$B$8:$B$51, 0))/100
C41: 2007 | D41: =IFERROR(E41/F41,"") | E41: =IF($C41<=2023,INDEX(PWT!$B$2:$B$35, MATCH($C41, PWT!$A$2:$A$35, 0)),$D$34*F41) | F41: =INDEX(WEO_Data!$C$8:$C$51, MATCH($C41, WEO_Data!$B$8:$B$51, 0))*1000 | G41: =IF($C41<=2023,INDEX($L$6:$L$27, MATCH($C41, $C$6:$C$27, 0)),TREND($L$6:$L$27, $C$6:$C$27, $C41)) | H41: =EXP(G41+$B$2*LN(E41)) | I41: =IF(AND($C41>=2026,$C41<=2033),INDEX(Investment!$C$2:$C$9, MATCH($C41, Investment!$B$2:$B$9, 0)),0) | J41: =IF($C41<2026,0,(1-$B$3)*J40+I41) | K41: =E41+J41 | L41: =EXP(G41+$B$2*LN(K41)) | M41: =L41-H41 | N41: =F41+M41 | O41: =IFERROR(N41/N40-1,"") | P41: =INDEX(WEO_Data!$D$8:$D$51, MATCH($C41, WEO_Data!$B$8:$B$51, 0))/100
C42: 2008 | D42: =IFERROR(E42/F42,"") | E42: =IF($C42<=2023,INDEX(PWT!$B$2:$B$35, MATCH($C42, PWT!$A$2:$A$35, 0)),$D$34*F42) | F42: =INDEX(WEO_Data!$C$8:$C$51, MATCH($C42, WEO_Data!$B$8:$B$51, 0))*1000 | G42: =IF($C42<=2023,INDEX($L$6:$L$27, MATCH($C42, $C$6:$C$27, 0)),TREND($L$6:$L$27, $C$6:$C$27, $C42)) | H42: =EXP(G42+$B$2*LN(E42)) | I42: =IF(AND($C42>=2026,$C42<=2033),INDEX(Investment!$C$2:$C$9, MATCH($C42, Investment!$B$2:$B$9, 0)),0) | J42: =IF($C42<2026,0,(1-$B$3)*J41+I42) | K42: =E42+J42 | L42: =EXP(G42+$B$2*LN(K42)) | M42: =L42-H42 | N42: =F42+M42 | O42: =IFERROR(N42/N41-1,"") | P42: =INDEX(WEO_Data!$D$8:$D$51, MATCH($C42, WEO_Data!$B$8:$B$51, 0))/100
C43: 2009 | D43: =IFERROR(E43/F43,"") | E43: =IF($C43<=2023,INDEX(PWT!$B$2:$B$35, MATCH($C43, PWT!$A$2:$A$35, 0)),$D$34*F43) | F43: =INDEX(WEO_Data!$C$8:$C$51, MATCH($C43, WEO_Data!$B$8:$B$51, 0))*1000 | G43: =IF($C43<=2023,INDEX($L$6:$L$27, MATCH($C43, $C$6:$C$27, 0)),TREND($L$6:$L$27, $C$6:$C$27, $C43)) | H43: =EXP(G43+$B$2*LN(E43)) | I43: =IF(AND($C43>=2026,$C43<=2033),INDEX(Investment!$C$2:$C$9, MATCH($C43, Investment!$B$2:$B$9, 0)),0) | J43: =IF($C43<2026,0,(1-$B$3)*J42+I43) | K43: =E43+J43 | L43: =EXP(G43+$B$2*LN(K43)) | M43: =L43-H43 | N43: =F43+M43 | O43: =IFERROR(N43/N42-1,"") | P43: =INDEX(WEO_Data!$D$8:$D$51, MATCH($C43, WEO_Data!$B$8:$B$51, 0))/100
C44: 2010 | D44: =IFERROR(E44/F44,"") | E44: =IF($C44<=2023,INDEX(PWT!$B$2:$B$35, MATCH($C44, PWT!$A$2:$A$35, 0)),$D$34*F44) | F44: =INDEX(WEO_Data!$C$8:$C$51, MATCH($C44, WEO_Data!$B$8:$B$51, 0))*1000 | G44: =IF($C44<=2023,INDEX($L$6:$L$27, MATCH($C44, $C$6:$C$27, 0)),TREND($L$6:$L$27, $C$6:$C$27, $C44)) | H44: =EXP(G44+$B$2*LN(E44)) | I44: =IF(AND($C44>=2026,$C44<=2033),INDEX(Investment!$C$2:$C$9, MATCH($C44, Investment!$B$2:$B$9, 0)),0) | J44: =IF($C44<2026,0,(1-$B$3)*J43+I44) | K44: =E44+J44 | L44: =EXP(G44+$B$2*LN(K44)) | M44: =L44-H44 | N44: =F44+M44 | O44: =IFERROR(N44/N43-1,"") | P44: =INDEX(WEO_Data!$D$8:$D$51, MATCH($C44, WEO_Data!$B$8:$B$51, 0))/100
C45: 2011 | D45: =IFERROR(E45/F45,"") | E45: =IF($C45<=2023,INDEX(PWT!$B$2:$B$35, MATCH($C45, PWT!$A$2:$A$35, 0)),$D$34*F45) | F45: =INDEX(WEO_Data!$C$8:$C$51, MATCH($C45, WEO_Data!$B$8:$B$51, 0))*1000 | G45: =IF($C45<=2023,INDEX($L$6:$L$27, MATCH($C45, $C$6:$C$27, 0)),TREND($L$6:$L$27, $C$6:$C$27, $C45)) | H45: =EXP(G45+$B$2*LN(E45)) | I45: =IF(AND($C45>=2026,$C45<=2033),INDEX(Investment!$C$2:$C$9, MATCH($C45, Investment!$B$2:$B$9, 0)),0) | J45: =IF($C45<2026,0,(1-$B$3)*J44+I45) | K45: =E45+J45 | L45: =EXP(G45+$B$2*LN(K45)) | M45: =L45-H45 | N45: =F45+M45 | O45: =IFERROR(N45/N44-1,"") | P45: =INDEX(WEO_Data!$D$8:$D$51, MATCH($C45, WEO_Data!$B$8:$B$51, 0))/100
C46: 2012 | D46: =IFERROR(E46/F46,"") | E46: =IF($C46<=2023,INDEX(PWT!$B$2:$B$35, MATCH($C46, PWT!$A$2:$A$35, 0)),$D$34*F46) | F46: =INDEX(WEO_Data!$C$8:$C$51, MATCH($C46, WEO_Data!$B$8:$B$51, 0))*1000 | G46: =IF($C46<=2023,INDEX($L$6:$L$27, MATCH($C46, $C$6:$C$27, 0)),TREND($L$6:$L$27, $C$6:$C$27, $C46)) | H46: =EXP(G46+$B$2*LN(E46)) | I46: =IF(AND($C46>=2026,$C46<=2033),INDEX(Investment!$C$2:$C$9, MATCH($C46, Investment!$B$2:$B$9, 0)),0) | J46: =IF($C46<2026,0,(1-$B$3)*J45+I46) | K46: =E46+J46 | L46: =EXP(G46+$B$2*LN(K46)) | M46: =L46-H46 | N46: =F46+M46 | O46: =IFERROR(N46/N45-1,"") | P46: =INDEX(WEO_Data!$D$8:$D$51, MATCH($C46, WEO_Data!$B$8:$B$51, 0))/100
C47: 2013 | D47: =IFERROR(E47/F47,"") | E47: =IF($C47<=2023,INDEX(PWT!$B$2:$B$35, MATCH($C47, PWT!$A$2:$A$35, 0)),$D$34*F47) | F47: =INDEX(WEO_Data!$C$8:$C$51, MATCH($C47, WEO_Data!$B$8:$B$51, 0))*1000 | G47: =IF($C47<=2023,INDEX($L$6:$L$27, MATCH($C47, $C$6:$C$27, 0)),TREND($L$6:$L$27, $C$6:$C$27, $C47)) | H47: =EXP(G47+$B$2*LN(E47)) | I47: =IF(AND($C47>=2026,$C47<=2033),INDEX(Investment!$C$2:$C$9, MATCH($C47, Investment!$B$2:$B$9, 0)),0) | J47: =IF($C47<2026,0,(1-$B$3)*J46+I47) | K47: =E47+J47 | L47: =EXP(G47+$B$2*LN(K47)) | M47: =L47-H47 | N47: =F47+M47 | O47: =IFERROR(N47/N46-1,"") | P47: =INDEX(WEO_Data!$D$8:$D$51, MATCH($C47, WEO_Data!$B$8:$B$51, 0))/100
C48: 2014 | D48: =IFERROR(E48/F48,"") | E48: =IF($C48<=2023,INDEX(PWT!$B$2:$B$35, MATCH($C48, PWT!$A$2:$A$35, 0)),$D$34*F48) | F48: =INDEX(WEO_Data!$C$8:$C$51, MATCH($C48, WEO_Data!$B$8:$B$51, 0))*1000 | G48: =IF($C48<=2023,INDEX($L$6:$L$27, MATCH($C48, $C$6:$C$27, 0)),TREND($L$6:$L$27, $C$6:$C$27, $C48)) | H48: =EXP(G48+$B$2*LN(E48)) | I48: =IF(AND($C48>=2026,$C48<=2033),INDEX(Investment!$C$2:$C$9, MATCH($C48, Investment!$B$2:$B$9, 0)),0) | J48: =IF($C48<2026,0,(1-$B$3)*J47+I48) | K48: =E48+J48 | L48: =EXP(G48+$B$2*LN(K48)) | M48: =L48-H48 | N48: =F48+M48 | O48: =IFERROR(N48/N47-1,"") | P48: =INDEX(WEO_Data!$D$8:$D$51, MATCH($C48, WEO_Data!$B$8:$B$51, 0))/100
... C75: 2041 | D75: =IFERROR(E75/F75,"") | E75: =IF($C75<=2023,INDEX(PWT!$B$2:$B$35, MATCH($C75, PWT!$A$2:$A$35, 0)),$D$34*F75) | F75: =INDEX(WEO_Data!$C$8:$C$51, MATCH($C75, WEO_Data!$B$8:$B$51, 0))*1000 | G75: =IF($C75<=2023,INDEX($L$6:$L$27, MATCH($C75, $C$6:$C$27, 0)),TREND($L$6:$L$27, $C$6:$C$27, $C75)) | H75: =EXP(G75+$B$2*LN(E75)) | I75: =IF(AND($C75>=2026,$C75<=2033),INDEX(Investment!$C$2:$C$9, MATCH($C75, Investment!$B$2:$B$9, 0)),0) | J75: =IF($C75<2026,0,(1-$B$3)*J74+I75) | K75: =E75+J75 | L75: =EXP(G75+$B$2*LN(K75)) | M75: =L75-H75 | N75: =F75+M75 | O75: =IFERROR(N75/N74-1,"") | P75: =INDEX(WEO_Data!$D$8:$D$51, MATCH($C75, WEO_Data!$B$8:$B$51, 0))/100

Sheet Investment
B1: Year | C1: Project Investment (Deflated) | D1: Profile weight | E1: Total investment (deflated, model units)
B2: 2026 | C2: =$E$2*D2/SUM($D$2:$D$9) | D2: 648.58931 | E2: 10583.813
B3: 2027 | C3: =$E$2*D3/SUM($D$2:$D$9) | D3: 1220.0802
B4: 2028 | C4: =$E$2*D4/SUM($D$2:$D$9) | D4: 1756.1737
B5: 2029 | C5: =$E$2*D5/SUM($D$2:$D$9) | D5: 2221.1947
B6: 2030 | C6: =$E$2*D6/SUM($D$2:$D$9) | D6: 2122.4679
B7: 2031 | C7: =$E$2*D7/SUM($D$2:$D$9) | D7: 1524.5246
B8: 2032 | C8: =$E$2*D8/SUM($D$2:$D$9) | D8: 738.17631
B9: 2033 | C9: =$E$2*D9/SUM($D$2:$D$9) | D9: 352.60598

Sheet CFC data
A1: DATE | B1: TIME PERIOD | C1: Consumption of fixed capital (IDCM.A.N.GE.W2.S1.S1.D.P51C.N1G._T._Z.XDC.V.N) | D1: Capital Stock | E1: Depreciation rate
A2: 35430 | B2: 1996 | C2: 304.51509 | D2: =INDEX(PWT!$B$2:$B$35, MATCH(B2, PWT!$A$2:$A$35, 0)) | E2: =IFERROR(C2/D2,"")
A3: 35795 | B3: 1997 | C3: 383.64166 | D3: =INDEX(PWT!$B$2:$B$35, MATCH(B3, PWT!$A$2:$A$35, 0)) | E3: =IFERROR(C3/D3,"")
A4: 36160 | B4: 1998 | C4: 516.39712 | D4: =INDEX(PWT!$B$2:$B$35, MATCH(B4, PWT!$A$2:$A$35, 0)) | E4: =IFERROR(C4/D4,"")
A5: 36525 | B5: 1999 | C5: 661.60383 | D5: =INDEX(PWT!$B$2:$B$35, MATCH(B5, PWT!$A$2:$A$35, 0)) | E5: =IFERROR(C5/D5,"")
A6: 36891 | B6: 2000 | C6: 631.701 | D6: =INDEX(PWT!$B$2:$B$35, MATCH(B6, PWT!$A$2:$A$35, 0)) | E6: =IFERROR(C6/D6,"")
A7: 37256 | B7: 2001 | C7: 706.98373 | D7: =INDEX(PWT!$B$2:$B$35, MATCH(B7, PWT!$A$2:$A$35, 0)) | E7: =IFERROR(C7/D7,"")
A8: 37621 | B8: 2002 | C8: 790.11257 | D8: =INDEX(PWT!$B$2:$B$35, MATCH(B8, PWT!$A$2:$A$35, 0)) | E8: =IFERROR(C8/D8,"")
A9: 37986 | B9: 2003 | C9: 932.91622 | D9: =INDEX(PWT!$B$2:$B$35, MATCH(B9, PWT!$A$2:$A$35, 0)) | E9: =IFERROR(C9/D9,"")
A10: 38352 | B10: 2004 | C10: 976.81854 | D10: =INDEX(PWT!$B$2:$B$35, MATCH(B10, PWT!$A$2:$A$35, 0)) | E10: =IFERROR(C10/D10,"")
A11: 38717 | B11: 2005 | C11: 1113.4501 | D11: =INDEX(PWT!$B$2:$B$35, MATCH(B11, PWT!$A$2:$A$35, 0)) | E11: =IFERROR(C11/D11,"")
A12: 39082 | B12: 2006 | C12: 1306.3731 | D12: =INDEX(PWT!$B$2:$B$35, MATCH(B12, PWT!$A$2:$A$35, 0)) | E12: =IFERROR(C12/D12,"")
A13: 39447 | B13: 2007 | C13: 1617.03 | D13: =INDEX(PWT!$B$2:$B$35, MATCH(B13, PWT!$A$2:$A$35, 0)) | E13: =IFERROR(C13/D13,"")
... A29: 45291 | B29: 2023 | C29: 9410.6578 | D29: =INDEX(PWT!$B$2:$B$35, MATCH(B29, PWT!$A$2:$A$35, 0)) | E29: =IFERROR(C29/D29,"")

Sheet PWT
A1: year | B1: rnna | C1: rgdpna
A2: 1990 | B2: 333953.91 | C2: 67440.055
A3: 1991 | B3: 336800.12 | C3: 53052.84
A4: 1992 | B4: 331575.34 | C4: 29442.938
A5: 1993 | B5: 318977.56 | C5: 20818.902
A6: 1994 | B6: 310557.22 | C6: 18657.664
A7: 1995 | B7: 305633.28 | C7: 19138.576
A8: 1996 | B8: 301706.47 | C8: 21298.572
A9: 1997 | B9: 298764.62 | C9: 23538.967
A10: 1998 | B10: 298990.5 | C10: 24269.842
A11: 1999 | B11: 299754.78 | C11: 24966.201
A12: 2000 | B12: 300383.31 | C12: 25425.168
A13: 2001 | B13: 302284.06 | C13: 26646.961
... A35: 2023 | B35: 426190.5 | C35: 91437.812

Sheet WEO_Data
B1: WEO Country Code | C1: 915 | D1: 915
B2: WEO Subject Code | C2: NGDP_R | D2: NGDP_RPCH
B3: Country | C3: Georgia | D3: Georgia
B4: Subject Descriptor | C4: Gross domestic product, constant prices | D4: Gross domestic product, constant prices
B5: Units | C5: National currency | D5: Percent change
B6: Scale | C6: Billions | D6: Units
B7: Country/Series-specific Notes | C7: Source: National Statistics Office. Historical data from 2010 revised in February 2024 Latest actual data: 2024 Notes: Data prior to 1996 cannot be confirmed by national sources. Data prior to 2010 are based on staff estimates. National accounts manual used: System of National Accounts (SNA) 2008 GDP valuation: Market prices Reporting in calendar year: Yes Start/end months of reporting year: January/December Base year: 2019 Chain-weighted: Yes, from 1996 Primary domestic currency: Georgian lari Data last updated: 04/09/2025 | D7: See notes for: Gross domestic product, constant prices (National currency).
B8: 2000 | C8: =PWT!C12/1000 | D8: 1.9
B9: 2001 | C9: =C8*(1+D9/100) | D9: 4.8
B10: 2002 | C10: =C9*(1+D10/100) | D10: 5.5
B11: 2003 | C11: =C10*(1+D11/100) | D11: 11.2
B12: 2004 | C12: =C11*(1+D12/100) | D12: 5.8
B13: 2005 | C13: =C12*(1+D13/100) | D13: 9.6
B14: 2006 | C14: =C13*(1+D14/100) | D14: 9.4
B15: 2007 | C15: =C14*(1+D15/100) | D15: 12.6
B16: 2008 | C16: =C15*(1+D16/100) | D16: 2.4
B17: 2009 | C17: =C16*(1+D17/100) | D17: -3.7
B18: 2010 | C18: =C17*(1+D18/100) | D18: 6.9
B19: 2011 | C19: =C18*(1+D19/100) | D19: 7.9
B20: 2012 | C20: =C19*(1+D20/100) | D20: 6.6
... B35: 2027 | C35: =C34*(1+D35/100) | D35: 5
B36: 2028 | C36: =C35*(1+D36/100) | D36: =$D$35
B37: 2029 | C37: =C36*(1+D37/100) | D37: =$D$35
B38: 2030 | C38: =C37*(1+D38/100) | D38: =$D$35
B39: 2031 | C39: =C38*(1+D39/100) | D39: =$D$35
B40: 2032 | C40: =C39*(1+D40/100) | D40: =$D$35
B41: 2033 | C41: =C40*(1+D41/100) | D41: =$D$35
B42: 2034 | C42: =C41*(1+D42/100) | D42: =$D$35
B43: 2035 | C43: =C42*(1+D43/100) | D43: =$D$35
B44: 2036 | C44: =C43*(1+D44/100) | D44: =$D$35
B45: 2037 | C45: =C44*(1+D45/100) | D45: =$D$35
B46: 2038 | C46: =C45*(1+D46/100) | D46: =$D$35
B47: 2039 | C47: =C46*(1+D47/100) | D47: =$D$35
... B51: 2043 | C51: =C50*(1+D51/100) | D51: =$D$35
B16385: WEO Country Code | C16385: 915 | D16385: 915
B16386: WEO Subject Code | C16386: NGDP_R | D16386: NGDP_RPCH
B16387: Country | C16387: Georgia | D16387: Georgia
B16388: Subject Descriptor | C16388: Gross domestic product, constant prices | D16388: Gross domestic product, constant prices
B16389: Units | C16389: National currency | D16389: Percent change
B16390: Scale | C16390: Billions | D16390: Units
...
